Workbook

Sheet Scheme Summary
B1: Turbolux Epoxy Campaign – Kerala: Sales Team Incentive Scheme
B2: Goal: 20 active epoxy dealers in every district · 14 districts × 20 = 280 epoxy dealers across Kerala
B4: Campaign period | C4: 01 Oct 2026 – 31 Dec 2026 (Q3). Only billing dated in this window counts. [Proposed – change if needed]
B5: Roles covered | C5: TSO (1 per district) · Coordinator (5 teams) · Area Sales Manager (South / Central / North) · Regional Sales Manager (Kerala).
B6: Main KPI – Active epoxy dealers (60%) | C6: Target 20 per district. An ACTIVE EPOXY DEALER is a dealer with net epoxy billing of at least 20 L in the campaign (after returns), with a display/shade card in the shop. Each dealer counts once, in the district where it is billed.
B7: Second KPI – Epoxy volume (40%) | C7: Net litres of the full epoxy range (floor coating, primer, self-levelling, PU topcoat, grout) against the district volume target. Returns, FOC and samples are deducted.
B8: How payout works | C8: Payout = Base × 60% × Dealer-slab % + Base × 40% × Volume-slab % + kickers, then capped and multiplied by the collection factor.
B9: Dealer slabs (of 20) | C9: <10 dealers → NIL (gate) · 10–13 → 40% · 14–15 → 60% · 16–17 → 80% · 18–19 → 90% · 20–24 → 100% · 25+ → 125%.
B10: Volume slabs | C10: <80% → 0 · 80–89.9% → 60% · 90–99.9% → 80% · 100–109.9% → 100% · 110–119.9% → 120% · ≥120% → 150%.
B11: Qualifying gate | C11: No incentive at all if active dealers are below 50% of target (fewer than 10 in a district, or 50% of the team/area/state total).
B12: TSO kickers | C12: ₹1,000 for each active dealer beyond 20 · ₹300 per repeat-order dealer (2 or more invoices) · ₹500 per applicator meet (max 4; at least 10 applicators; photos and attendance sheet) · Top 3 districts that reach 20 dealers: ₹10,000 / ₹7,000 / ₹5,000.
B13: Coordinator kickers | C13: ₹500 per team dealer beyond target · ₹150 per repeat-order dealer · ₹5,000 team bonus if at least 60% of own districts reach 20 dealers.
B14: ASM kickers | C14: ₹300 per area dealer beyond target · ₹10,000 area bonus if every district in the area reaches at least 15 dealers.
B15: RSM kickers | C15: ₹200 per Kerala dealer beyond 280 · ₹15,000 region bonus if Kerala reaches 280 dealers AND epoxy collection is at least 95%.
... B20: Using this file | C20: Edit only YELLOW cells with BLUE text: district rows on the TSO sheet, collection % on each sheet, and rates on Parameters. Everything else is a formula. Names, volume targets and actuals are SAMPLE values – replace them with SAP data.

Sheet Payout Summary
A1: Campaign Payout Summary – Kerala Epoxy
A3: Role | B3: Headcount | C3: Total Payout (₹) | D3: Earning >0 | E3: Avg per Head (₹)
A4: TSO | B4: =COUNTA('TSO Incentive'!$B$5:$B$18) -> 14 | C4: ='TSO Incentive'!AB19 -> 249125 | D4: =COUNTIF('TSO Incentive'!$AB$5:$AB$18,">0") -> 13 | E4: =IFERROR(C4/B4,0) -> 17794.643
A5: Coordinator | B5: =COUNTA('Coordinator Incentive'!B5:B9) -> 5 | C5: ='Coordinator Incentive'!Y10 -> 119325 | D5: =COUNTIF('Coordinator Incentive'!Y5:Y9,">0") -> 5 | E5: =IFERROR(C5/B5,0) -> 23865
A6: Area Sales Manager | B6: =COUNTA('ASM Incentive'!B5:B7) -> 3 | C6: ='ASM Incentive'!Y8 -> 94600 | D6: =COUNTIF('ASM Incentive'!Y5:Y7,">0") -> 3 | E6: =IFERROR(C6/B6,0) -> 31533.333
A7: Regional Sales Manager | B7: =1 -> 1 | C7: ='RSM Incentive'!B23 -> 47000 | D7: =IF('RSM Incentive'!B23>0,1,0) -> 1 | E7: =IFERROR(C7/B7,0) -> 47000
A8: TOTAL | B8: =SUM(B4:B7) -> 23 | C8: =SUM(C4:C7) -> 510050 | D8: =SUM(D4:D7) -> 22
A10: Campaign scorecard & economics
A11: Active epoxy dealer target (Kerala) | B11: ='RSM Incentive'!B5 -> 280
A12: Active epoxy dealers achieved | B12: ='RSM Incentive'!B6 -> 261
A13: Dealer achievement % | B13: ='RSM Incentive'!B7 -> 0.93214286
A14: Districts at 20+ dealers | B14: =COUNTIF('TSO Incentive'!$H$5:$H$18,">=1") -> 7
A15: Epoxy volume target (L) | B15: ='RSM Incentive'!B10 -> 10400
A16: Net epoxy volume (L) | B16: ='RSM Incentive'!B11 -> 10600
A17: Volume achievement % | B17: ='RSM Incentive'!B12 -> 1.0192308
A18: Incentive cost per active dealer (₹) | B18: =IFERROR(C8/B12,0) -> 1954.2146
A19: Incentive cost per litre (₹/L) | B19: =IFERROR(C8/B16,0) -> 48.117925
A20: Avg net realisation (₹/L) – input | B20: 420
A21: Epoxy sales value (₹) | B21: =B16*B20 -> 4452000
A22: Incentive cost as % of sales | B22: =IFERROR(C8/B21,0) -> 0.11456649
A24: Note: dealer activation is an investment in future epoxy sales, so the first-quarter cost % can run higher than a normal volume scheme.

Sheet District Dealer Tracker
A1: District-wise Epoxy Dealer Tracker – Road to 280
A2: Shows the gap to 20 dealers per district. Updates from 'TSO Incentive'.
A4: District | B4: Area | C4: Coordinator | D4: Target | E4: Active Dealers | F4: Gap to 20 | G4: Achv % | H4: Status | I4: Next slab at (dealers) | J4: Dealers needed for next slab
A5: ='TSO Incentive'!C5 -> Thiruvananthapuram | B5: ='TSO Incentive'!E5 -> South | C5: ='TSO Incentive'!D5 -> Coord-1 | D5: ='TSO Incentive'!F5 -> 20 | E5: ='TSO Incentive'!G5 -> 22 | F5: =MAX(0,D5-E5) -> 0 | G5: =IFERROR(E5/D5,0) -> 1.1 | H5: =IF(G5>=1,"Target met",IF(G5>=0.8,"Close",IF(G5>=Parameters!$B$51,"Qualifying","Below gate"))) -> Target met | I5: =IFERROR(INDEX(Parameters!$A$20:$A$26,MATCH(G5,Parameters!$A$20:$A$26,1)+1)*D5,"Top slab") -> 25 | J5: =IF(ISNUMBER(I5),MAX(0,ROUNDUP(I5,0)-E5),0) -> 3
A6: ='TSO Incentive'!C6 -> Kollam | B6: ='TSO Incentive'!E6 -> South | C6: ='TSO Incentive'!D6 -> Coord-1 | D6: ='TSO Incentive'!F6 -> 20 | E6: ='TSO Incentive'!G6 -> 19 | F6: =MAX(0,D6-E6) -> 1 | G6: =IFERROR(E6/D6,0) -> 0.95 | H6: =IF(G6>=1,"Target met",IF(G6>=0.8,"Close",IF(G6>=Parameters!$B$51,"Qualifying","Below gate"))) -> Close | I6: =IFERROR(INDEX(Parameters!$A$20:$A$26,MATCH(G6,Parameters!$A$20:$A$26,1)+1)*D6,"Top slab") -> 20 | J6: =IF(ISNUMBER(I6),MAX(0,ROUNDUP(I6,0)-E6),0) -> 1
A7: ='TSO Incentive'!C7 -> Pathanamthitta | B7: ='TSO Incentive'!E7 -> South | C7: ='TSO Incentive'!D7 -> Coord-1 | D7: ='TSO Incentive'!F7 -> 20 | E7: ='TSO Incentive'!G7 -> 15 | F7: =MAX(0,D7-E7) -> 5 | G7: =IFERROR(E7/D7,0) -> 0.75 | H7: =IF(G7>=1,"Target met",IF(G7>=0.8,"Close",IF(G7>=Parameters!$B$51,"Qualifying","Below gate"))) -> Qualifying | I7: =IFERROR(INDEX(Parameters!$A$20:$A$26,MATCH(G7,Parameters!$A$20:$A$26,1)+1)*D7,"Top slab") -> 16 | J7: =IF(ISNUMBER(I7),MAX(0,ROUNDUP(I7,0)-E7),0) -> 1
A8: ='TSO Incentive'!C8 -> Alappuzha | B8: ='TSO Incentive'!E8 -> South | C8: ='TSO Incentive'!D8 -> Coord-2 | D8: ='TSO Incentive'!F8 -> 20 | E8: ='TSO Incentive'!G8 -> 20 | F8: =MAX(0,D8-E8) -> 0 | G8: =IFERROR(E8/D8,0) -> 1 | H8: =IF(G8>=1,"Target met",IF(G8>=0.8,"Close",IF(G8>=Parameters!$B$51,"Qualifying","Below gate"))) -> Target met | I8: =IFERROR(INDEX(Parameters!$A$20:$A$26,MATCH(G8,Parameters!$A$20:$A$26,1)+1)*D8,"Top slab") -> 25 | J8: =IF(ISNUMBER(I8),MAX(0,ROUNDUP(I8,0)-E8),0) -> 5
A9: ='TSO Incentive'!C9 -> Kottayam | B9: ='TSO Incentive'!E9 -> Central | C9: ='TSO Incentive'!D9 -> Coord-2 | D9: ='TSO Incentive'!F9 -> 20 | E9: ='TSO Incentive'!G9 -> 21 | F9: =MAX(0,D9-E9) -> 0 | G9: =IFERROR(E9/D9,0) -> 1.05 | H9: =IF(G9>=1,"Target met",IF(G9>=0.8,"Close",IF(G9>=Parameters!$B$51,"Qualifying","Below gate"))) -> Target met | I9: =IFERROR(INDEX(Parameters!$A$20:$A$26,MATCH(G9,Parameters!$A$20:$A$26,1)+1)*D9,"Top slab") -> 25 | J9: =IF(ISNUMBER(I9),MAX(0,ROUNDUP(I9,0)-E9),0) -> 4
A10: ='TSO Incentive'!C10 -> Idukki | B10: ='TSO Incentive'!E10 -> Central | C10: ='TSO Incentive'!D10 -> Coord-2 | D10: ='TSO Incentive'!F10 -> 20 | E10: ='TSO Incentive'!G10 -> 13 | F10: =MAX(0,D10-E10) -> 7 | G10: =IFERROR(E10/D10,0) -> 0.65 | H10: =IF(G10>=1,"Target met",IF(G10>=0.8,"Close",IF(G10>=Parameters!$B$51,"Qualifying","Below gate"))) -> Qualifying | I10: =IFERROR(INDEX(Parameters!$A$20:$A$26,MATCH(G10,Parameters!$A$20:$A$26,1)+1)*D10,"Top slab") -> 14 | J10: =IF(ISNUMBER(I10),MAX(0,ROUNDUP(I10,0)-E10),0) -> 1
A11: ='TSO Incentive'!C11 -> Ernakulam | B11: ='TSO Incentive'!E11 -> Central | C11: ='TSO Incentive'!D11 -> Coord-3 | D11: ='TSO Incentive'!F11 -> 20 | E11: ='TSO Incentive'!G11 -> 26 | F11: =MAX(0,D11-E11) -> 0 | G11: =IFERROR(E11/D11,0) -> 1.3 | H11: =IF(G11>=1,"Target met",IF(G11>=0.8,"Close",IF(G11>=Parameters!$B$51,"Qualifying","Below gate"))) -> Target met | I11: =IFERROR(INDEX(Parameters!$A$20:$A$26,MATCH(G11,Parameters!$A$20:$A$26,1)+1)*D11,"Top slab") -> Top slab | J11: =IF(ISNUMBER(I11),MAX(0,ROUNDUP(I11,0)-E11),0) -> 0
A12: ='TSO Incentive'!C12 -> Thrissur | B12: ='TSO Incentive'!E12 -> Central | C12: ='TSO Incentive'!D12 -> Coord-3 | D12: ='TSO Incentive'!F12 -> 20 | E12: ='TSO Incentive'!G12 -> 20 | F12: =MAX(0,D12-E12) -> 0 | G12: =IFERROR(E12/D12,0) -> 1 | H12: =IF(G12>=1,"Target met",IF(G12>=0.8,"Close",IF(G12>=Parameters!$B$51,"Qualifying","Below gate"))) -> Target met | I12: =IFERROR(INDEX(Parameters!$A$20:$A$26,MATCH(G12,Parameters!$A$20:$A$26,1)+1)*D12,"Top slab") -> 25 | J12: =IF(ISNUMBER(I12),MAX(0,ROUNDUP(I12,0)-E12),0) -> 5
A13: ='TSO Incentive'!C13 -> Palakkad | B13: ='TSO Incentive'!E13 -> North | C13: ='TSO Incentive'!D13 -> Coord-4 | D13: ='TSO Incentive'!F13 -> 20 | E13: ='TSO Incentive'!G13 -> 17 | F13: =MAX(0,D13-E13) -> 3 | G13: =IFERROR(E13/D13,0) -> 0.85 | H13: =IF(G13>=1,"Target met",IF(G13>=0.8,"Close",IF(G13>=Parameters!$B$51,"Qualifying","Below gate"))) -> Close | I13: =IFERROR(INDEX(Parameters!$A$20:$A$26,MATCH(G13,Parameters!$A$20:$A$26,1)+1)*D13,"Top slab") -> 18 | J13: =IF(ISNUMBER(I13),MAX(0,ROUNDUP(I13,0)-E13),0) -> 1
A14: ='TSO Incentive'!C14 -> Malappuram | B14: ='TSO Incentive'!E14 -> North | C14: ='TSO Incentive'!D14 -> Coord-4 | D14: ='TSO Incentive'!F14 -> 20 | E14: ='TSO Incentive'!G14 -> 21 | F14: =MAX(0,D14-E14) -> 0 | G14: =IFERROR(E14/D14,0) -> 1.05 | H14: =IF(G14>=1,"Target met",IF(G14>=0.8,"Close",IF(G14>=Parameters!$B$51,"Qualifying","Below gate"))) -> Target met | I14: =IFERROR(INDEX(Parameters!$A$20:$A$26,MATCH(G14,Parameters!$A$20:$A$26,1)+1)*D14,"Top slab") -> 25 | J14: =IF(ISNUMBER(I14),MAX(0,ROUNDUP(I14,0)-E14),0) -> 4
A15: ='TSO Incentive'!C15 -> Kozhikode | B15: ='TSO Incentive'!E15 -> North | C15: ='TSO Incentive'!D15 -> Coord-4 | D15: ='TSO Incentive'!F15 -> 20 | E15: ='TSO Incentive'!G15 -> 23 | F15: =MAX(0,D15-E15) -> 0 | G15: =IFERROR(E15/D15,0) -> 1.15 | H15: =IF(G15>=1,"Target met",IF(G15>=0.8,"Close",IF(G15>=Parameters!$B$51,"Qualifying","Below gate"))) -> Target met | I15: =IFERROR(INDEX(Parameters!$A$20:$A$26,MATCH(G15,Parameters!$A$20:$A$26,1)+1)*D15,"Top slab") -> 25 | J15: =IF(ISNUMBER(I15),MAX(0,ROUNDUP(I15,0)-E15),0) -> 2
A16: ='TSO Incentive'!C16 -> Wayanad | B16: ='TSO Incentive'!E16 -> North | C16: ='TSO Incentive'!D16 -> Coord-5 | D16: ='TSO Incentive'!F16 -> 20 | E16: ='TSO Incentive'!G16 -> 12 | F16: =MAX(0,D16-E16) -> 8 | G16: =IFERROR(E16/D16,0) -> 0.6 | H16: =IF(G16>=1,"Target met",IF(G16>=0.8,"Close",IF(G16>=Parameters!$B$51,"Qualifying","Below gate"))) -> Qualifying | I16: =IFERROR(INDEX(Parameters!$A$20:$A$26,MATCH(G16,Parameters!$A$20:$A$26,1)+1)*D16,"Top slab") -> 14 | J16: =IF(ISNUMBER(I16),MAX(0,ROUNDUP(I16,0)-E16),0) -> 2
... A18: ='TSO Incentive'!C18 -> Kasaragod | B18: ='TSO Incentive'!E18 -> North | C18: ='TSO Incentive'!D18 -> Coord-5 | D18: ='TSO Incentive'!F18 -> 20 | E18: ='TSO Incentive'!G18 -> 14 | F18: =MAX(0,D18-E18) -> 6 | G18: =IFERROR(E18/D18,0) -> 0.7 | H18: =IF(G18>=1,"Target met",IF(G18>=0.8,"Close",IF(G18>=Parameters!$B$51,"Qualifying","Below gate"))) -> Qualifying | I18: =IFERROR(INDEX(Parameters!$A$20:$A$26,MATCH(G18,Parameters!$A$20:$A$26,1)+1)*D18,"Top slab") -> 16 | J18: =IF(ISNUMBER(I18),MAX(0,ROUNDUP(I18,0)-E18),0) -> 2
A19: KERALA | D19: =SUM(D5:D18) -> 280 | E19: =SUM(E5:E18) -> 261 | F19: =SUM(F5:F18) -> 32 | G19: =IFERROR(E19/D19,0) -> 0.93214286 | J19: =SUM(J5:J18) -> 33

Sheet Parameters
A1: Scheme Parameters (edit yellow cells – all calculators update)
A4: Rate / rule | B4: TSO | C4: Coordinator | D4: ASM | E4: RSM | F4: Note
A5: Base incentive for campaign (₹) | B5: 15000 | C5: 20000 | D5: 30000 | E5: 50000 | F5: Paid at 100% on both KPIs. Proposed – align with budget.
A6: Weight – active dealer count | B6: 0.6 | C6: 0.6 | D6: 0.6 | E6: 0.6 | F6: Main KPI.
A7: Weight – epoxy volume | B7: 0.4 | C7: 0.4 | D7: 0.4 | E7: 0.4 | F7: Must add to 100% with the row above.
A8: Extra dealer bonus (₹ per dealer beyond target) | B8: 1000 | C8: 500 | D8: 300 | E8: 200 | F8: On active dealers above own / team / area / state target.
A9: Repeat-order dealer bonus (₹ per dealer) | B9: 300 | C9: 150 | D9: 0 | E9: 0 | F9: Dealer with 2+ epoxy invoices in the campaign.
A10: Applicator meet (₹ per meet) | B10: 500 | C10: 0 | D10: 0 | E10: 0 | F10: At least 10 applicators; photos and attendance sheet.
A11: Max applicator meets paid | B11: 4 | C11: 0 | D11: 0 | E11: 0 | F11: Per TSO for the campaign.
A12: Team / Area / Region bonus (₹) | B12: 0 | C12: 5000 | D12: 10000 | E12: 15000 | F12: Conditions in rows 48–50.
A13: Cap (multiple of base incentive) | B13: 2 | C13: 2 | D13: 2 | E13: 2 | F13: Top-performer award is paid over the cap.
A15: Active epoxy dealer target per district | B15: 20 | F15: Your target: 20 dealers in each district.
A16: Minimum net litres for an 'active' dealer | B16: 20 | F16: Used when you count dealers from SAP (rule only).
A18: Active dealer slabs (achievement vs target; 20 dealers = 100%)
A19: Achievement from (≥) | B19: Dealers (of 20) | C19: Payout %
A20: 0 | B20: 0 – 9 | C20: 0
A21: 0.5 | B21: 10 – 13 | C21: 0.4
A22: 0.7 | B22: 14 – 15 | C22: 0.6
A23: 0.8 | B23: 16 – 17 | C23: 0.8
A24: 0.9 | B24: 18 – 19 | C24: 0.9
A25: 1 | B25: 20 – 24 | C25: 1
A26: 1.25 | B26: 25 and above | C26: 1.25
A28: Epoxy volume slabs
A29: Achievement from (≥) | B29: Band | C29: Payout %
A30: 0 | B30: Below 80% | C30: 0
A31: 0.8 | B31: 80% – 89.9% | C31: 0.6
A32: 0.9 | B32: 90% – 99.9% | C32: 0.8
A33: 1 | B33: 100% – 109.9% | C33: 1
A34: 1.1 | B34: 110% – 119.9% | C34: 1.2
A35: 1.2 | B35: 120% and above | C35: 1.5
A37: Collection factor (% of campaign epoxy billing collected by 31-Jan-2027)
A38: Collection from (≥) | B38: Band | C38: Multiplier
A39: 0 | B39: Below 80% | C39: 0
A40: 0.8 | B40: 80% – 89.9% | C40: 0.75
A41: 0.9 | B41: 90% and above | C41: 1
A43: TSO top-performer award (district must reach dealer target)
A44: Rank (by active dealers) | B44: Award (₹)
A45: 1 | B45: 10000 | F45: Ties share the rank (both get the award).
A46: 2 | B46: 7000
A47: 3 | B47: 5000
...

Sheet TSO Incentive
A1: TSO Incentive Calculator – Kerala Epoxy Campaign (Oct–Dec 2026) · Target 20 active dealers per district
A2: Yellow/blue = input. Names, volume targets and actuals are SAMPLE values – replace them with SAP data.
A4: S.No | B4: TSO Name | C4: District | D4: Coordinator | E4: Area | F4: Dealer Target | G4: Active Epoxy Dealers | H4: Dealer Achv % | I4: Dealer Slab % | J4: Dealer Payout (₹) | K4: Volume Target (L) | L4: Net Volume (L) | M4: Volume Achv % | N4: Volume Slab % | O4: Volume Payout (₹) | P4: Dealers beyond Target | Q4: Extra Dealer Bonus (₹) | R4: Repeat-order Dealers | S4: Repeat Bonus (₹) | T4: Applicator Meets | U4: Meet Bonus (₹) | V4: Rank (at target) | W4: Top Award (₹) | X4: Gross before Cap (₹) | Y4: Cap (₹) | Z4: Collection % | AA4: Collection Factor | AB4: FINAL PAYOUT (₹)
A5: 1 | B5: TSO – THI | C5: Thiruvananthapuram | D5: Coord-1 | E5: South | F5: =Parameters!$B$15 -> 20 | G5: 22 | H5: =IFERROR(G5/F5,0) -> 1.1 | I5: =INDEX(Parameters!$C$20:$C$26,MATCH(H5,Parameters!$A$20:$A$26,1)) -> 1 | J5: =Parameters!$B$5*Parameters!$B$6*I5 -> 9000 | K5: 900 | L5: 1010 | M5: =IFERROR(L5/K5,0) -> 1.1222222 | N5: =INDEX(Parameters!$C$30:$C$35,MATCH(M5,Parameters!$A$30:$A$35,1)) -> 1.2 | O5: =Parameters!$B$5*Parameters!$B$7*N5 -> 7200 | P5: =MAX(0,G5-F5) -> 2 | Q5: =P5*Parameters!$B$8 -> 2000 | R5: 9 | S5: =MIN(R5,G5)*Parameters!$B$9 -> 2700 | T5: 4 | U5: =MIN(T5,Parameters!$B$11)*Parameters!$B$10 -> 2000 | V5: =IF(H5>=1,1+COUNTIFS($H$5:$H$18,">"&H5,$H$5:$H$18,">=1"),"") -> 3 | W5: =IF(AND(ISNUMBER(V5),V5<=3),INDEX(Parameters!$B$45:$B$47,V5),0) -> 5000 | X5: =J5+O5+Q5+S5+U5 -> 22900 | Y5: =Parameters!$B$13*Parameters!$B$5 -> 30000 | Z5: 0.93 | AA5: =INDEX(Parameters!$C$39:$C$41,MATCH(Z5,Parameters!$A$39:$A$41,1)) -> 1 | AB5: =IF(H5<Parameters!$B$51,0,(MIN(X5,Y5)+W5)*AA5) -> 27900
A6: 2 | B6: TSO – KOL | C6: Kollam | D6: Coord-1 | E6: South | F6: =Parameters!$B$15 -> 20 | G6: 19 | H6: =IFERROR(G6/F6,0) -> 0.95 | I6: =INDEX(Parameters!$C$20:$C$26,MATCH(H6,Parameters!$A$20:$A$26,1)) -> 0.9 | J6: =Parameters!$B$5*Parameters!$B$6*I6 -> 8100 | K6: 800 | L6: 760 | M6: =IFERROR(L6/K6,0) -> 0.95 | N6: =INDEX(Parameters!$C$30:$C$35,MATCH(M6,Parameters!$A$30:$A$35,1)) -> 0.8 | O6: =Parameters!$B$5*Parameters!$B$7*N6 -> 4800 | P6: =MAX(0,G6-F6) -> 0 | Q6: =P6*Parameters!$B$8 -> 0 | R6: 7 | S6: =MIN(R6,G6)*Parameters!$B$9 -> 2100 | T6: 4 | U6: =MIN(T6,Parameters!$B$11)*Parameters!$B$10 -> 2000 | V6: =IF(H6>=1,1+COUNTIFS($H$5:$H$18,">"&H6,$H$5:$H$18,">=1"),"") | W6: =IF(AND(ISNUMBER(V6),V6<=3),INDEX(Parameters!$B$45:$B$47,V6),0) -> 0 | X6: =J6+O6+Q6+S6+U6 -> 17000 | Y6: =Parameters!$B$13*Parameters!$B$5 -> 30000 | Z6: 0.91 | AA6: =INDEX(Parameters!$C$39:$C$41,MATCH(Z6,Parameters!$A$39:$A$41,1)) -> 1 | AB6: =IF(H6<Parameters!$B$51,0,(MIN(X6,Y6)+W6)*AA6) -> 17000
A7: 3 | B7: TSO – PAT | C7: Pathanamthitta | D7: Coord-1 | E7: South | F7: =Parameters!$B$15 -> 20 | G7: 15 | H7: =IFERROR(G7/F7,0) -> 0.75 | I7: =INDEX(Parameters!$C$20:$C$26,MATCH(H7,Parameters!$A$20:$A$26,1)) -> 0.6 | J7: =Parameters!$B$5*Parameters!$B$6*I7 -> 5400 | K7: 600 | L7: 540 | M7: =IFERROR(L7/K7,0) -> 0.9 | N7: =INDEX(Parameters!$C$30:$C$35,MATCH(M7,Parameters!$A$30:$A$35,1)) -> 0.8 | O7: =Parameters!$B$5*Parameters!$B$7*N7 -> 4800 | P7: =MAX(0,G7-F7) -> 0 | Q7: =P7*Parameters!$B$8 -> 0 | R7: 5 | S7: =MIN(R7,G7)*Parameters!$B$9 -> 1500 | T7: 3 | U7: =MIN(T7,Parameters!$B$11)*Parameters!$B$10 -> 1500 | V7: =IF(H7>=1,1+COUNTIFS($H$5:$H$18,">"&H7,$H$5:$H$18,">=1"),"") | W7: =IF(AND(ISNUMBER(V7),V7<=3),INDEX(Parameters!$B$45:$B$47,V7),0) -> 0 | X7: =J7+O7+Q7+S7+U7 -> 13200 | Y7: =Parameters!$B$13*Parameters!$B$5 -> 30000 | Z7: 0.88 | AA7: =INDEX(Parameters!$C$39:$C$41,MATCH(Z7,Parameters!$A$39:$A$41,1)) -> 0.75 | AB7: =IF(H7<Parameters!$B$51,0,(MIN(X7,Y7)+W7)*AA7) -> 9900
A8: 4 | B8: TSO – ALA | C8: Alappuzha | D8: Coord-2 | E8: South | F8: =Parameters!$B$15 -> 20 | G8: 20 | H8: =IFERROR(G8/F8,0) -> 1 | I8: =INDEX(Parameters!$C$20:$C$26,MATCH(H8,Parameters!$A$20:$A$26,1)) -> 1 | J8: =Parameters!$B$5*Parameters!$B$6*I8 -> 9000 | K8: 700 | L8: 720 | M8: =IFERROR(L8/K8,0) -> 1.0285714 | N8: =INDEX(Parameters!$C$30:$C$35,MATCH(M8,Parameters!$A$30:$A$35,1)) -> 1 | O8: =Parameters!$B$5*Parameters!$B$7*N8 -> 6000 | P8: =MAX(0,G8-F8) -> 0 | Q8: =P8*Parameters!$B$8 -> 0 | R8: 8 | S8: =MIN(R8,G8)*Parameters!$B$9 -> 2400 | T8: 4 | U8: =MIN(T8,Parameters!$B$11)*Parameters!$B$10 -> 2000 | V8: =IF(H8>=1,1+COUNTIFS($H$5:$H$18,">"&H8,$H$5:$H$18,">=1"),"") -> 6 | W8: =IF(AND(ISNUMBER(V8),V8<=3),INDEX(Parameters!$B$45:$B$47,V8),0) -> 0 | X8: =J8+O8+Q8+S8+U8 -> 19400 | Y8: =Parameters!$B$13*Parameters!$B$5 -> 30000 | Z8: 0.95 | AA8: =INDEX(Parameters!$C$39:$C$41,MATCH(Z8,Parameters!$A$39:$A$41,1)) -> 1 | AB8: =IF(H8<Parameters!$B$51,0,(MIN(X8,Y8)+W8)*AA8) -> 19400
A9: 5 | B9: TSO – KOT | C9: Kottayam | D9: Coord-2 | E9: Central | F9: =Parameters!$B$15 -> 20 | G9: 21 | H9: =IFERROR(G9/F9,0) -> 1.05 | I9: =INDEX(Parameters!$C$20:$C$26,MATCH(H9,Parameters!$A$20:$A$26,1)) -> 1 | J9: =Parameters!$B$5*Parameters!$B$6*I9 -> 9000 | K9: 800 | L9: 850 | M9: =IFERROR(L9/K9,0) -> 1.0625 | N9: =INDEX(Parameters!$C$30:$C$35,MATCH(M9,Parameters!$A$30:$A$35,1)) -> 1 | O9: =Parameters!$B$5*Parameters!$B$7*N9 -> 6000 | P9: =MAX(0,G9-F9) -> 1 | Q9: =P9*Parameters!$B$8 -> 1000 | R9: 9 | S9: =MIN(R9,G9)*Parameters!$B$9 -> 2700 | T9: 4 | U9: =MIN(T9,Parameters!$B$11)*Parameters!$B$10 -> 2000 | V9: =IF(H9>=1,1+COUNTIFS($H$5:$H$18,">"&H9,$H$5:$H$18,">=1"),"") -> 4 | W9: =IF(AND(ISNUMBER(V9),V9<=3),INDEX(Parameters!$B$45:$B$47,V9),0) -> 0 | X9: =J9+O9+Q9+S9+U9 -> 20700 | Y9: =Parameters!$B$13*Parameters!$B$5 -> 30000 | Z9: 0.92 | AA9: =INDEX(Parameters!$C$39:$C$41,MATCH(Z9,Parameters!$A$39:$A$41,1)) -> 1 | AB9: =IF(H9<Parameters!$B$51,0,(MIN(X9,Y9)+W9)*AA9) -> 20700
A10: 6 | B10: TSO – IDU | C10: Idukki | D10: Coord-2 | E10: Central | F10: =Parameters!$B$15 -> 20 | G10: 13 | H10: =IFERROR(G10/F10,0) -> 0.65 | I10: =INDEX(Parameters!$C$20:$C$26,MATCH(H10,Parameters!$A$20:$A$26,1)) -> 0.4 | J10: =Parameters!$B$5*Parameters!$B$6*I10 -> 3600 | K10: 500 | L10: 410 | M10: =IFERROR(L10/K10,0) -> 0.82 | N10: =INDEX(Parameters!$C$30:$C$35,MATCH(M10,Parameters!$A$30:$A$35,1)) -> 0.6 | O10: =Parameters!$B$5*Parameters!$B$7*N10 -> 3600 | P10: =MAX(0,G10-F10) -> 0 | Q10: =P10*Parameters!$B$8 -> 0 | R10: 4 | S10: =MIN(R10,G10)*Parameters!$B$9 -> 1200 | T10: 2 | U10: =MIN(T10,Parameters!$B$11)*Parameters!$B$10 -> 1000 | V10: =IF(H10>=1,1+COUNTIFS($H$5:$H$18,">"&H10,$H$5:$H$18,">=1"),"") | W10: =IF(AND(ISNUMBER(V10),V10<=3),INDEX(Parameters!$B$45:$B$47,V10),0) -> 0 | X10: =J10+O10+Q10+S10+U10 -> 9400 | Y10: =Parameters!$B$13*Parameters!$B$5 -> 30000 | Z10: 0.85 | AA10: =INDEX(Parameters!$C$39:$C$41,MATCH(Z10,Parameters!$A$39:$A$41,1)) -> 0.75 | AB10: =IF(H10<Parameters!$B$51,0,(MIN(X10,Y10)+W10)*AA10) -> 7050
A11: 7 | B11: TSO – ERN | C11: Ernakulam | D11: Coord-3 | E11: Central | F11: =Parameters!$B$15 -> 20 | G11: 26 | H11: =IFERROR(G11/F11,0) -> 1.3 | I11: =INDEX(Parameters!$C$20:$C$26,MATCH(H11,Parameters!$A$20:$A$26,1)) -> 1.25 | J11: =Parameters!$B$5*Parameters!$B$6*I11 -> 11250 | K11: 1200 | L11: 1420 | M11: =IFERROR(L11/K11,0) -> 1.1833333 | N11: =INDEX(Parameters!$C$30:$C$35,MATCH(M11,Parameters!$A$30:$A$35,1)) -> 1.2 | O11: =Parameters!$B$5*Parameters!$B$7*N11 -> 7200 | P11: =MAX(0,G11-F11) -> 6 | Q11: =P11*Parameters!$B$8 -> 6000 | R11: 12 | S11: =MIN(R11,G11)*Parameters!$B$9 -> 3600 | T11: 4 | U11: =MIN(T11,Parameters!$B$11)*Parameters!$B$10 -> 2000 | V11: =IF(H11>=1,1+COUNTIFS($H$5:$H$18,">"&H11,$H$5:$H$18,">=1"),"") -> 1 | W11: =IF(AND(ISNUMBER(V11),V11<=3),INDEX(Parameters!$B$45:$B$47,V11),0) -> 10000 | X11: =J11+O11+Q11+S11+U11 -> 30050 | Y11: =Parameters!$B$13*Parameters!$B$5 -> 30000 | Z11: 0.94 | AA11: =INDEX(Parameters!$C$39:$C$41,MATCH(Z11,Parameters!$A$39:$A$41,1)) -> 1 | AB11: =IF(H11<Parameters!$B$51,0,(MIN(X11,Y11)+W11)*AA11) -> 40000
A12: 8 | B12: TSO – THR | C12: Thrissur | D12: Coord-3 | E12: Central | F12: =Parameters!$B$15 -> 20 | G12: 20 | H12: =IFERROR(G12/F12,0) -> 1 | I12: =INDEX(Parameters!$C$20:$C$26,MATCH(H12,Parameters!$A$20:$A$26,1)) -> 1 | J12: =Parameters!$B$5*Parameters!$B$6*I12 -> 9000 | K12: 900 | L12: 880 | M12: =IFERROR(L12/K12,0) -> 0.97777778 | N12: =INDEX(Parameters!$C$30:$C$35,MATCH(M12,Parameters!$A$30:$A$35,1)) -> 0.8 | O12: =Parameters!$B$5*Parameters!$B$7*N12 -> 4800 | P12: =MAX(0,G12-F12) -> 0 | Q12: =P12*Parameters!$B$8 -> 0 | R12: 8 | S12: =MIN(R12,G12)*Parameters!$B$9 -> 2400 | T12: 4 | U12: =MIN(T12,Parameters!$B$11)*Parameters!$B$10 -> 2000 | V12: =IF(H12>=1,1+COUNTIFS($H$5:$H$18,">"&H12,$H$5:$H$18,">=1"),"") -> 6 | W12: =IF(AND(ISNUMBER(V12),V12<=3),INDEX(Parameters!$B$45:$B$47,V12),0) -> 0 | X12: =J12+O12+Q12+S12+U12 -> 18200 | Y12: =Parameters!$B$13*Parameters!$B$5 -> 30000 | Z12: 0.92 | AA12: =INDEX(Parameters!$C$39:$C$41,MATCH(Z12,Parameters!$A$39:$A$41,1)) -> 1 | AB12: =IF(H12<Parameters!$B$51,0,(MIN(X12,Y12)+W12)*AA12) -> 18200
A13: 9 | B13: TSO – PAL | C13: Palakkad | D13: Coord-4 | E13: North | F13: =Parameters!$B$15 -> 20 | G13: 17 | H13: =IFERROR(G13/F13,0) -> 0.85 | I13: =INDEX(Parameters!$C$20:$C$26,MATCH(H13,Parameters!$A$20:$A$26,1)) -> 0.8 | J13: =Parameters!$B$5*Parameters!$B$6*I13 -> 7200 | K13: 700 | L13: 640 | M13: =IFERROR(L13/K13,0) -> 0.91428571 | N13: =INDEX(Parameters!$C$30:$C$35,MATCH(M13,Parameters!$A$30:$A$35,1)) -> 0.8 | O13: =Parameters!$B$5*Parameters!$B$7*N13 -> 4800 | P13: =MAX(0,G13-F13) -> 0 | Q13: =P13*Parameters!$B$8 -> 0 | R13: 6 | S13: =MIN(R13,G13)*Parameters!$B$9 -> 1800 | T13: 3 | U13: =MIN(T13,Parameters!$B$11)*Parameters!$B$10 -> 1500 | V13: =IF(H13>=1,1+COUNTIFS($H$5:$H$18,">"&H13,$H$5:$H$18,">=1"),"") | W13: =IF(AND(ISNUMBER(V13),V13<=3),INDEX(Parameters!$B$45:$B$47,V13),0) -> 0 | X13: =J13+O13+Q13+S13+U13 -> 15300 | Y13: =Parameters!$B$13*Parameters!$B$5 -> 30000 | Z13: 0.86 | AA13: =INDEX(Parameters!$C$39:$C$41,MATCH(Z13,Parameters!$A$39:$A$41,1)) -> 0.75 | AB13: =IF(H13<Parameters!$B$51,0,(MIN(X13,Y13)+W13)*AA13) -> 11475
A14: 10 | B14: TSO – MAL | C14: Malappuram | D14: Coord-4 | E14: North | F14: =Parameters!$B$15 -> 20 | G14: 21 | H14: =IFERROR(G14/F14,0) -> 1.05 | I14: =INDEX(Parameters!$C$20:$C$26,MATCH(H14,Parameters!$A$20:$A$26,1)) -> 1 | J14: =Parameters!$B$5*Parameters!$B$6*I14 -> 9000 | K14: 800 | L14: 900 | M14: =IFERROR(L14/K14,0) -> 1.125 | N14: =INDEX(Parameters!$C$30:$C$35,MATCH(M14,Parameters!$A$30:$A$35,1)) -> 1.2 | O14: =Parameters!$B$5*Parameters!$B$7*N14 -> 7200 | P14: =MAX(0,G14-F14) -> 1 | Q14: =P14*Parameters!$B$8 -> 1000 | R14: 9 | S14: =MIN(R14,G14)*Parameters!$B$9 -> 2700 | T14: 4 | U14: =MIN(T14,Parameters!$B$11)*Parameters!$B$10 -> 2000 | V14: =IF(H14>=1,1+COUNTIFS($H$5:$H$18,">"&H14,$H$5:$H$18,">=1"),"") -> 4 | W14: =IF(AND(ISNUMBER(V14),V14<=3),INDEX(Parameters!$B$45:$B$47,V14),0) -> 0 | X14: =J14+O14+Q14+S14+U14 -> 21900 | Y14: =Parameters!$B$13*Parameters!$B$5 -> 30000 | Z14: 0.93 | AA14: =INDEX(Parameters!$C$39:$C$41,MATCH(Z14,Parameters!$A$39:$A$41,1)) -> 1 | AB14: =IF(H14<Parameters!$B$51,0,(MIN(X14,Y14)+W14)*AA14) -> 21900
A15: 11 | B15: TSO – KOZ | C15: Kozhikode | D15: Coord-4 | E15: North | F15: =Parameters!$B$15 -> 20 | G15: 23 | H15: =IFERROR(G15/F15,0) -> 1.15 | I15: =INDEX(Parameters!$C$20:$C$26,MATCH(H15,Parameters!$A$20:$A$26,1)) -> 1 | J15: =Parameters!$B$5*Parameters!$B$6*I15 -> 9000 | K15: 900 | L15: 980 | M15: =IFERROR(L15/K15,0) -> 1.0888889 | N15: =INDEX(Parameters!$C$30:$C$35,MATCH(M15,Parameters!$A$30:$A$35,1)) -> 1 | O15: =Parameters!$B$5*Parameters!$B$7*N15 -> 6000 | P15: =MAX(0,G15-F15) -> 3 | Q15: =P15*Parameters!$B$8 -> 3000 | R15: 10 | S15: =MIN(R15,G15)*Parameters!$B$9 -> 3000 | T15: 4 | U15: =MIN(T15,Parameters!$B$11)*Parameters!$B$10 -> 2000 | V15: =IF(H15>=1,1+COUNTIFS($H$5:$H$18,">"&H15,$H$5:$H$18,">=1"),"") -> 2 | W15: =IF(AND(ISNUMBER(V15),V15<=3),INDEX(Parameters!$B$45:$B$47,V15),0) -> 7000 | X15: =J15+O15+Q15+S15+U15 -> 23000 | Y15: =Parameters!$B$13*Parameters!$B$5 -> 30000 | Z15: 0.96 | AA15: =INDEX(Parameters!$C$39:$C$41,MATCH(Z15,Parameters!$A$39:$A$41,1)) -> 1 | AB15: =IF(H15<Parameters!$B$51,0,(MIN(X15,Y15)+W15)*AA15) -> 30000
A16: 12 | B16: TSO – WAY | C16: Wayanad | D16: Coord-5 | E16: North | F16: =Parameters!$B$15 -> 20 | G16: 12 | H16: =IFERROR(G16/F16,0) -> 0.6 | I16: =INDEX(Parameters!$C$20:$C$26,MATCH(H16,Parameters!$A$20:$A$26,1)) -> 0.4 | J16: =Parameters!$B$5*Parameters!$B$6*I16 -> 3600 | K16: 400 | L16: 330 | M16: =IFERROR(L16/K16,0) -> 0.825 | N16: =INDEX(Parameters!$C$30:$C$35,MATCH(M16,Parameters!$A$30:$A$35,1)) -> 0.6 | O16: =Parameters!$B$5*Parameters!$B$7*N16 -> 3600 | P16: =MAX(0,G16-F16) -> 0 | Q16: =P16*Parameters!$B$8 -> 0 | R16: 3 | S16: =MIN(R16,G16)*Parameters!$B$9 -> 900 | T16: 2 | U16: =MIN(T16,Parameters!$B$11)*Parameters!$B$10 -> 1000 | V16: =IF(H16>=1,1+COUNTIFS($H$5:$H$18,">"&H16,$H$5:$H$18,">=1"),"") | W16: =IF(AND(ISNUMBER(V16),V16<=3),INDEX(Parameters!$B$45:$B$47,V16),0) -> 0 | X16: =J16+O16+Q16+S16+U16 -> 9100 | Y16: =Parameters!$B$13*Parameters!$B$5 -> 30000 | Z16: 0.9 | AA16: =INDEX(Parameters!$C$39:$C$41,MATCH(Z16,Parameters!$A$39:$A$41,1)) -> 1 | AB16: =IF(H16<Parameters!$B$51,0,(MIN(X16,Y16)+W16)*AA16) -> 9100
... A18: 14 | B18: TSO – KAS | C18: Kasaragod | D18: Coord-5 | E18: North | F18: =Parameters!$B$15 -> 20 | G18: 14 | H18: =IFERROR(G18/F18,0) -> 0.7 | I18: =INDEX(Parameters!$C$20:$C$26,MATCH(H18,Parameters!$A$20:$A$26,1)) -> 0.6 | J18: =Parameters!$B$5*Parameters!$B$6*I18 -> 5400 | K18: 500 | L18: 470 | M18: =IFERROR(L18/K18,0) -> 0.94 | N18: =INDEX(Parameters!$C$30:$C$35,MATCH(M18,Parameters!$A$30:$A$35,1)) -> 0.8 | O18: =Parameters!$B$5*Parameters!$B$7*N18 -> 4800 | P18: =MAX(0,G18-F18) -> 0 | Q18: =P18*Parameters!$B$8 -> 0 | R18: 4 | S18: =MIN(R18,G18)*Parameters!$B$9 -> 1200 | T18: 2 | U18: =MIN(T18,Parameters!$B$11)*Parameters!$B$10 -> 1000 | V18: =IF(H18>=1,1+COUNTIFS($H$5:$H$18,">"&H18,$H$5:$H$18,">=1"),"") | W18: =IF(AND(ISNUMBER(V18),V18<=3),INDEX(Parameters!$B$45:$B$47,V18),0) -> 0 | X18: =J18+O18+Q18+S18+U18 -> 12400 | Y18: =Parameters!$B$13*Parameters!$B$5 -> 30000 | Z18: 0.78 | AA18: =INDEX(Parameters!$C$39:$C$41,MATCH(Z18,Parameters!$A$39:$A$41,1)) -> 0 | AB18: =IF(H18<Parameters!$B$51,0,(MIN(X18,Y18)+W18)*AA18) -> 0
B19: KERALA TOTAL | F19: =SUM(F5:F18) -> 280 | G19: =SUM(G5:G18) -> 261 | H19: =IFERROR(G19/F19,0) -> 0.93214286 | J19: =SUM(J5:J18) -> 106650 | K19: =SUM(K5:K18) -> 10400 | L19: =SUM(L5:L18) -> 10600 | M19: =IFERROR(L19/K19,0) -> 1.0192308 | O19: =SUM(O5:O18) -> 75600 | P19: =SUM(P5:P18) -> 13 | Q19: =SUM(Q5:Q18) -> 13000 | R19: =SUM(R5:R18) -> 101 | S19: =SUM(S5:S18) -> 30300 | T19: =SUM(T5:T18) -> 47 | U19: =SUM(U5:U18) -> 23500 | W19: =SUM(W5:W18) -> 22000 | X19: =SUM(X5:X18) -> 249050 | Y19: =SUM(Y5:Y18) -> 420000 | Z19: =IFERROR(SUMPRODUCT(L5:L18,Z5:Z18)/L19,0) -> 0.91365094 | AB19: =SUM(AB5:AB18) -> 249125
B21: Districts at 20+ dealers: | G21: =COUNTIF(H5:H18,">=1")&" of "&COUNTA(C5:C18) -> 7 of 14

Sheet Coordinator Incentive
A1: Coordinator Incentive Calculator – Kerala Epoxy Campaign
A2: Dealers, volume and repeat orders roll up from 'TSO Incentive'. The only input here is Collection %.
A4: S.No | B4: Name | C4: Districts | D4: Dealer Target | E4: Active Dealers | F4: Dealer Achv % | G4: Dealer Slab % | H4: Dealer Payout (₹) | I4: Volume Target (L) | J4: Net Volume (L) | K4: Volume Achv % | L4: Volume Slab % | M4: Volume Payout (₹) | N4: Dealers beyond Target | O4: Extra Dealer Bonus (₹) | P4: Repeat-order Dealers | Q4: Repeat Bonus (₹) | R4: % Districts at 20+ | S4: Bonus Condition | T4: Team/Area Bonus (₹) | U4: Gross before Cap (₹) | V4: Cap (₹) | W4: Collection % | X4: Collection Factor | Y4: FINAL PAYOUT (₹)
A5: 1 | B5: Coord-1 | C5: =COUNTIF('TSO Incentive'!$D$5:$D$18,B5) -> 3 | D5: =SUMIFS('TSO Incentive'!$F$5:$F$18,'TSO Incentive'!$D$5:$D$18,$B5) -> 60 | E5: =SUMIFS('TSO Incentive'!$G$5:$G$18,'TSO Incentive'!$D$5:$D$18,$B5) -> 56 | F5: =IFERROR(E5/D5,0) -> 0.93333333 | G5: =INDEX(Parameters!$C$20:$C$26,MATCH(F5,Parameters!$A$20:$A$26,1)) -> 0.9 | H5: =Parameters!$C$5*Parameters!$C$6*G5 -> 10800 | I5: =SUMIFS('TSO Incentive'!$K$5:$K$18,'TSO Incentive'!$D$5:$D$18,$B5) -> 2300 | J5: =SUMIFS('TSO Incentive'!$L$5:$L$18,'TSO Incentive'!$D$5:$D$18,$B5) -> 2310 | K5: =IFERROR(J5/I5,0) -> 1.0043478 | L5: =INDEX(Parameters!$C$30:$C$35,MATCH(K5,Parameters!$A$30:$A$35,1)) -> 1 | M5: =Parameters!$C$5*Parameters!$C$7*L5 -> 8000 | N5: =MAX(0,E5-D5) -> 0 | O5: =N5*Parameters!$C$8 -> 0 | P5: =SUMIFS('TSO Incentive'!$R$5:$R$18,'TSO Incentive'!$D$5:$D$18,$B5) -> 21 | Q5: =P5*Parameters!$C$9 -> 3150 | R5: =IFERROR(COUNTIFS('TSO Incentive'!$D$5:$D$18,B5,'TSO Incentive'!$H$5:$H$18,">=1")/C5,0) -> 0.33333333 | S5: =IF(R5>=Parameters!$B$48,"Met","Not met") -> Not met | T5: =IF(S5="Met",Parameters!$C$12,0) -> 0 | U5: =H5+M5+O5+Q5+T5 -> 21950 | V5: =Parameters!$C$13*Parameters!$C$5 -> 40000 | W5: 0.91 | X5: =INDEX(Parameters!$C$39:$C$41,MATCH(W5,Parameters!$A$39:$A$41,1)) -> 1 | Y5: =IF(F5<Parameters!$B$51,0,MIN(U5,V5)*X5) -> 21950
A6: 2 | B6: Coord-2 | C6: =COUNTIF('TSO Incentive'!$D$5:$D$18,B6) -> 3 | D6: =SUMIFS('TSO Incentive'!$F$5:$F$18,'TSO Incentive'!$D$5:$D$18,$B6) -> 60 | E6: =SUMIFS('TSO Incentive'!$G$5:$G$18,'TSO Incentive'!$D$5:$D$18,$B6) -> 54 | F6: =IFERROR(E6/D6,0) -> 0.9 | G6: =INDEX(Parameters!$C$20:$C$26,MATCH(F6,Parameters!$A$20:$A$26,1)) -> 0.9 | H6: =Parameters!$C$5*Parameters!$C$6*G6 -> 10800 | I6: =SUMIFS('TSO Incentive'!$K$5:$K$18,'TSO Incentive'!$D$5:$D$18,$B6) -> 2000 | J6: =SUMIFS('TSO Incentive'!$L$5:$L$18,'TSO Incentive'!$D$5:$D$18,$B6) -> 1980 | K6: =IFERROR(J6/I6,0) -> 0.99 | L6: =INDEX(Parameters!$C$30:$C$35,MATCH(K6,Parameters!$A$30:$A$35,1)) -> 0.8 | M6: =Parameters!$C$5*Parameters!$C$7*L6 -> 6400 | N6: =MAX(0,E6-D6) -> 0 | O6: =N6*Parameters!$C$8 -> 0 | P6: =SUMIFS('TSO Incentive'!$R$5:$R$18,'TSO Incentive'!$D$5:$D$18,$B6) -> 21 | Q6: =P6*Parameters!$C$9 -> 3150 | R6: =IFERROR(COUNTIFS('TSO Incentive'!$D$5:$D$18,B6,'TSO Incentive'!$H$5:$H$18,">=1")/C6,0) -> 0.66666667 | S6: =IF(R6>=Parameters!$B$48,"Met","Not met") -> Met | T6: =IF(S6="Met",Parameters!$C$12,0) -> 5000 | U6: =H6+M6+O6+Q6+T6 -> 25350 | V6: =Parameters!$C$13*Parameters!$C$5 -> 40000 | W6: 0.91 | X6: =INDEX(Parameters!$C$39:$C$41,MATCH(W6,Parameters!$A$39:$A$41,1)) -> 1 | Y6: =IF(F6<Parameters!$B$51,0,MIN(U6,V6)*X6) -> 25350
A7: 3 | B7: Coord-3 | C7: =COUNTIF('TSO Incentive'!$D$5:$D$18,B7) -> 2 | D7: =SUMIFS('TSO Incentive'!$F$5:$F$18,'TSO Incentive'!$D$5:$D$18,$B7) -> 40 | E7: =SUMIFS('TSO Incentive'!$G$5:$G$18,'TSO Incentive'!$D$5:$D$18,$B7) -> 46 | F7: =IFERROR(E7/D7,0) -> 1.15 | G7: =INDEX(Parameters!$C$20:$C$26,MATCH(F7,Parameters!$A$20:$A$26,1)) -> 1 | H7: =Parameters!$C$5*Parameters!$C$6*G7 -> 12000 | I7: =SUMIFS('TSO Incentive'!$K$5:$K$18,'TSO Incentive'!$D$5:$D$18,$B7) -> 2100 | J7: =SUMIFS('TSO Incentive'!$L$5:$L$18,'TSO Incentive'!$D$5:$D$18,$B7) -> 2300 | K7: =IFERROR(J7/I7,0) -> 1.0952381 | L7: =INDEX(Parameters!$C$30:$C$35,MATCH(K7,Parameters!$A$30:$A$35,1)) -> 1 | M7: =Parameters!$C$5*Parameters!$C$7*L7 -> 8000 | N7: =MAX(0,E7-D7) -> 6 | O7: =N7*Parameters!$C$8 -> 3000 | P7: =SUMIFS('TSO Incentive'!$R$5:$R$18,'TSO Incentive'!$D$5:$D$18,$B7) -> 20 | Q7: =P7*Parameters!$C$9 -> 3000 | R7: =IFERROR(COUNTIFS('TSO Incentive'!$D$5:$D$18,B7,'TSO Incentive'!$H$5:$H$18,">=1")/C7,0) -> 1 | S7: =IF(R7>=Parameters!$B$48,"Met","Not met") -> Met | T7: =IF(S7="Met",Parameters!$C$12,0) -> 5000 | U7: =H7+M7+O7+Q7+T7 -> 31000 | V7: =Parameters!$C$13*Parameters!$C$5 -> 40000 | W7: 0.93 | X7: =INDEX(Parameters!$C$39:$C$41,MATCH(W7,Parameters!$A$39:$A$41,1)) -> 1 | Y7: =IF(F7<Parameters!$B$51,0,MIN(U7,V7)*X7) -> 31000
A8: 4 | B8: Coord-4 | C8: =COUNTIF('TSO Incentive'!$D$5:$D$18,B8) -> 3 | D8: =SUMIFS('TSO Incentive'!$F$5:$F$18,'TSO Incentive'!$D$5:$D$18,$B8) -> 60 | E8: =SUMIFS('TSO Incentive'!$G$5:$G$18,'TSO Incentive'!$D$5:$D$18,$B8) -> 61 | F8: =IFERROR(E8/D8,0) -> 1.0166667 | G8: =INDEX(Parameters!$C$20:$C$26,MATCH(F8,Parameters!$A$20:$A$26,1)) -> 1 | H8: =Parameters!$C$5*Parameters!$C$6*G8 -> 12000 | I8: =SUMIFS('TSO Incentive'!$K$5:$K$18,'TSO Incentive'!$D$5:$D$18,$B8) -> 2400 | J8: =SUMIFS('TSO Incentive'!$L$5:$L$18,'TSO Incentive'!$D$5:$D$18,$B8) -> 2520 | K8: =IFERROR(J8/I8,0) -> 1.05 | L8: =INDEX(Parameters!$C$30:$C$35,MATCH(K8,Parameters!$A$30:$A$35,1)) -> 1 | M8: =Parameters!$C$5*Parameters!$C$7*L8 -> 8000 | N8: =MAX(0,E8-D8) -> 1 | O8: =N8*Parameters!$C$8 -> 500 | P8: =SUMIFS('TSO Incentive'!$R$5:$R$18,'TSO Incentive'!$D$5:$D$18,$B8) -> 25 | Q8: =P8*Parameters!$C$9 -> 3750 | R8: =IFERROR(COUNTIFS('TSO Incentive'!$D$5:$D$18,B8,'TSO Incentive'!$H$5:$H$18,">=1")/C8,0) -> 0.66666667 | S8: =IF(R8>=Parameters!$B$48,"Met","Not met") -> Met | T8: =IF(S8="Met",Parameters!$C$12,0) -> 5000 | U8: =H8+M8+O8+Q8+T8 -> 29250 | V8: =Parameters!$C$13*Parameters!$C$5 -> 40000 | W8: 0.92 | X8: =INDEX(Parameters!$C$39:$C$41,MATCH(W8,Parameters!$A$39:$A$41,1)) -> 1 | Y8: =IF(F8<Parameters!$B$51,0,MIN(U8,V8)*X8) -> 29250
A9: 5 | B9: Coord-5 | C9: =COUNTIF('TSO Incentive'!$D$5:$D$18,B9) -> 3 | D9: =SUMIFS('TSO Incentive'!$F$5:$F$18,'TSO Incentive'!$D$5:$D$18,$B9) -> 60 | E9: =SUMIFS('TSO Incentive'!$G$5:$G$18,'TSO Incentive'!$D$5:$D$18,$B9) -> 44 | F9: =IFERROR(E9/D9,0) -> 0.73333333 | G9: =INDEX(Parameters!$C$20:$C$26,MATCH(F9,Parameters!$A$20:$A$26,1)) -> 0.6 | H9: =Parameters!$C$5*Parameters!$C$6*G9 -> 7200 | I9: =SUMIFS('TSO Incentive'!$K$5:$K$18,'TSO Incentive'!$D$5:$D$18,$B9) -> 1600 | J9: =SUMIFS('TSO Incentive'!$L$5:$L$18,'TSO Incentive'!$D$5:$D$18,$B9) -> 1490 | K9: =IFERROR(J9/I9,0) -> 0.93125 | L9: =INDEX(Parameters!$C$30:$C$35,MATCH(K9,Parameters!$A$30:$A$35,1)) -> 0.8 | M9: =Parameters!$C$5*Parameters!$C$7*L9 -> 6400 | N9: =MAX(0,E9-D9) -> 0 | O9: =N9*Parameters!$C$8 -> 0 | P9: =SUMIFS('TSO Incentive'!$R$5:$R$18,'TSO Incentive'!$D$5:$D$18,$B9) -> 14 | Q9: =P9*Parameters!$C$9 -> 2100 | R9: =IFERROR(COUNTIFS('TSO Incentive'!$D$5:$D$18,B9,'TSO Incentive'!$H$5:$H$18,">=1")/C9,0) -> 0 | S9: =IF(R9>=Parameters!$B$48,"Met","Not met") -> Not met | T9: =IF(S9="Met",Parameters!$C$12,0) -> 0 | U9: =H9+M9+O9+Q9+T9 -> 15700 | V9: =Parameters!$C$13*Parameters!$C$5 -> 40000 | W9: 0.87 | X9: =INDEX(Parameters!$C$39:$C$41,MATCH(W9,Parameters!$A$39:$A$41,1)) -> 0.75 | Y9: =IF(F9<Parameters!$B$51,0,MIN(U9,V9)*X9) -> 11775
B10: TOTAL | C10: =SUM(C5:C9) -> 14 | D10: =SUM(D5:D9) -> 280 | E10: =SUM(E5:E9) -> 261 | F10: =IFERROR(E10/D10,0) -> 0.93214286 | H10: =SUM(H5:H9) -> 52800 | I10: =SUM(I5:I9) -> 10400 | J10: =SUM(J5:J9) -> 10600 | K10: =IFERROR(J10/I10,0) -> 1.0192308 | M10: =SUM(M5:M9) -> 36800 | N10: =SUM(N5:N9) -> 7 | O10: =SUM(O5:O9) -> 3500 | P10: =SUM(P5:P9) -> 101 | Q10: =SUM(Q5:Q9) -> 15150 | T10: =SUM(T5:T9) -> 15000 | U10: =SUM(U5:U9) -> 123250 | V10: =SUM(V5:V9) -> 200000 | W10: =IFERROR(SUMPRODUCT(J5:J9,W5:W9)/J10,0) -> 0.91109434 | Y10: =SUM(Y5:Y9) -> 119325

Sheet ASM Incentive
A1: Area Sales Manager Incentive Calculator – Kerala Epoxy Campaign
A2: Dealers, volume and repeat orders roll up from 'TSO Incentive'. The only input here is Collection %.
A4: S.No | B4: Name | C4: Districts | D4: Dealer Target | E4: Active Dealers | F4: Dealer Achv % | G4: Dealer Slab % | H4: Dealer Payout (₹) | I4: Volume Target (L) | J4: Net Volume (L) | K4: Volume Achv % | L4: Volume Slab % | M4: Volume Payout (₹) | N4: Dealers beyond Target | O4: Extra Dealer Bonus (₹) | P4: Repeat-order Dealers | Q4: Repeat Bonus (₹) | R4: Districts below min dealers | S4: Bonus Condition | T4: Team/Area Bonus (₹) | U4: Gross before Cap (₹) | V4: Cap (₹) | W4: Collection % | X4: Collection Factor | Y4: FINAL PAYOUT (₹)
A5: 1 | B5: South | C5: =COUNTIF('TSO Incentive'!$E$5:$E$18,B5) -> 4 | D5: =SUMIFS('TSO Incentive'!$F$5:$F$18,'TSO Incentive'!$E$5:$E$18,$B5) -> 80 | E5: =SUMIFS('TSO Incentive'!$G$5:$G$18,'TSO Incentive'!$E$5:$E$18,$B5) -> 76 | F5: =IFERROR(E5/D5,0) -> 0.95 | G5: =INDEX(Parameters!$C$20:$C$26,MATCH(F5,Parameters!$A$20:$A$26,1)) -> 0.9 | H5: =Parameters!$D$5*Parameters!$D$6*G5 -> 16200 | I5: =SUMIFS('TSO Incentive'!$K$5:$K$18,'TSO Incentive'!$E$5:$E$18,$B5) -> 3000 | J5: =SUMIFS('TSO Incentive'!$L$5:$L$18,'TSO Incentive'!$E$5:$E$18,$B5) -> 3030 | K5: =IFERROR(J5/I5,0) -> 1.01 | L5: =INDEX(Parameters!$C$30:$C$35,MATCH(K5,Parameters!$A$30:$A$35,1)) -> 1 | M5: =Parameters!$D$5*Parameters!$D$7*L5 -> 12000 | N5: =MAX(0,E5-D5) -> 0 | O5: =N5*Parameters!$D$8 -> 0 | P5: =SUMIFS('TSO Incentive'!$R$5:$R$18,'TSO Incentive'!$E$5:$E$18,$B5) -> 29 | Q5: =P5*Parameters!$D$9 -> 0 | R5: =COUNTIFS('TSO Incentive'!$E$5:$E$18,B5,'TSO Incentive'!$G$5:$G$18,"<"&Parameters!$B$49) -> 0 | S5: =IF(R5=0,"Met","Not met") -> Met | T5: =IF(S5="Met",Parameters!$D$12,0) -> 10000 | U5: =H5+M5+O5+Q5+T5 -> 38200 | V5: =Parameters!$D$13*Parameters!$D$5 -> 60000 | W5: 0.92 | X5: =INDEX(Parameters!$C$39:$C$41,MATCH(W5,Parameters!$A$39:$A$41,1)) -> 1 | Y5: =IF(F5<Parameters!$B$51,0,MIN(U5,V5)*X5) -> 38200
A6: 2 | B6: Central | C6: =COUNTIF('TSO Incentive'!$E$5:$E$18,B6) -> 4 | D6: =SUMIFS('TSO Incentive'!$F$5:$F$18,'TSO Incentive'!$E$5:$E$18,$B6) -> 80 | E6: =SUMIFS('TSO Incentive'!$G$5:$G$18,'TSO Incentive'!$E$5:$E$18,$B6) -> 80 | F6: =IFERROR(E6/D6,0) -> 1 | G6: =INDEX(Parameters!$C$20:$C$26,MATCH(F6,Parameters!$A$20:$A$26,1)) -> 1 | H6: =Parameters!$D$5*Parameters!$D$6*G6 -> 18000 | I6: =SUMIFS('TSO Incentive'!$K$5:$K$18,'TSO Incentive'!$E$5:$E$18,$B6) -> 3400 | J6: =SUMIFS('TSO Incentive'!$L$5:$L$18,'TSO Incentive'!$E$5:$E$18,$B6) -> 3560 | K6: =IFERROR(J6/I6,0) -> 1.0470588 | L6: =INDEX(Parameters!$C$30:$C$35,MATCH(K6,Parameters!$A$30:$A$35,1)) -> 1 | M6: =Parameters!$D$5*Parameters!$D$7*L6 -> 12000 | N6: =MAX(0,E6-D6) -> 0 | O6: =N6*Parameters!$D$8 -> 0 | P6: =SUMIFS('TSO Incentive'!$R$5:$R$18,'TSO Incentive'!$E$5:$E$18,$B6) -> 33 | Q6: =P6*Parameters!$D$9 -> 0 | R6: =COUNTIFS('TSO Incentive'!$E$5:$E$18,B6,'TSO Incentive'!$G$5:$G$18,"<"&Parameters!$B$49) -> 1 | S6: =IF(R6=0,"Met","Not met") -> Not met | T6: =IF(S6="Met",Parameters!$D$12,0) -> 0 | U6: =H6+M6+O6+Q6+T6 -> 30000 | V6: =Parameters!$D$13*Parameters!$D$5 -> 60000 | W6: 0.92 | X6: =INDEX(Parameters!$C$39:$C$41,MATCH(W6,Parameters!$A$39:$A$41,1)) -> 1 | Y6: =IF(F6<Parameters!$B$51,0,MIN(U6,V6)*X6) -> 30000
A7: 3 | B7: North | C7: =COUNTIF('TSO Incentive'!$E$5:$E$18,B7) -> 6 | D7: =SUMIFS('TSO Incentive'!$F$5:$F$18,'TSO Incentive'!$E$5:$E$18,$B7) -> 120 | E7: =SUMIFS('TSO Incentive'!$G$5:$G$18,'TSO Incentive'!$E$5:$E$18,$B7) -> 105 | F7: =IFERROR(E7/D7,0) -> 0.875 | G7: =INDEX(Parameters!$C$20:$C$26,MATCH(F7,Parameters!$A$20:$A$26,1)) -> 0.8 | H7: =Parameters!$D$5*Parameters!$D$6*G7 -> 14400 | I7: =SUMIFS('TSO Incentive'!$K$5:$K$18,'TSO Incentive'!$E$5:$E$18,$B7) -> 4000 | J7: =SUMIFS('TSO Incentive'!$L$5:$L$18,'TSO Incentive'!$E$5:$E$18,$B7) -> 4010 | K7: =IFERROR(J7/I7,0) -> 1.0025 | L7: =INDEX(Parameters!$C$30:$C$35,MATCH(K7,Parameters!$A$30:$A$35,1)) -> 1 | M7: =Parameters!$D$5*Parameters!$D$7*L7 -> 12000 | N7: =MAX(0,E7-D7) -> 0 | O7: =N7*Parameters!$D$8 -> 0 | P7: =SUMIFS('TSO Incentive'!$R$5:$R$18,'TSO Incentive'!$E$5:$E$18,$B7) -> 39 | Q7: =P7*Parameters!$D$9 -> 0 | R7: =COUNTIFS('TSO Incentive'!$E$5:$E$18,B7,'TSO Incentive'!$G$5:$G$18,"<"&Parameters!$B$49) -> 2 | S7: =IF(R7=0,"Met","Not met") -> Not met | T7: =IF(S7="Met",Parameters!$D$12,0) -> 0 | U7: =H7+M7+O7+Q7+T7 -> 26400 | V7: =Parameters!$D$13*Parameters!$D$5 -> 60000 | W7: 0.9 | X7: =INDEX(Parameters!$C$39:$C$41,MATCH(W7,Parameters!$A$39:$A$41,1)) -> 1 | Y7: =IF(F7<Parameters!$B$51,0,MIN(U7,V7)*X7) -> 26400
B8: TOTAL | C8: =SUM(C5:C7) -> 14 | D8: =SUM(D5:D7) -> 280 | E8: =SUM(E5:E7) -> 261 | F8: =IFERROR(E8/D8,0) -> 0.93214286 | H8: =SUM(H5:H7) -> 48600 | I8: =SUM(I5:I7) -> 10400 | J8: =SUM(J5:J7) -> 10600 | K8: =IFERROR(J8/I8,0) -> 1.0192308 | M8: =SUM(M5:M7) -> 36000 | N8: =SUM(N5:N7) -> 0 | O8: =SUM(O5:O7) -> 0 | P8: =SUM(P5:P7) -> 101 | Q8: =SUM(Q5:Q7) -> 0 | T8: =SUM(T5:T7) -> 10000 | U8: =SUM(U5:U7) -> 94600 | V8: =SUM(V5:V7) -> 180000 | W8: =IFERROR(SUMPRODUCT(J5:J7,W5:W7)/J8,0) -> 0.91243396 | Y8: =SUM(Y5:Y7) -> 94600

Sheet RSM Incentive
A1: Regional Sales Manager Incentive – Kerala
A3: Item | B3: Value | C3: Note
A4: RSM Name | B4: RSM – Kerala | C4: input
A5: Kerala Dealer Target | B5: =SUM('TSO Incentive'!$F$5:$F$18) -> 280 | C5: 14 districts × 20 = 280 (from TSO sheet)
A6: Active Epoxy Dealers – Kerala | B6: =SUM('TSO Incentive'!$G$5:$G$18) -> 261 | C6: From TSO sheet
A7: Dealer Achievement % | B7: =IFERROR(B6/B5,0) -> 0.93214286
A8: Dealer Slab % | B8: =INDEX(Parameters!$C$20:$C$26,MATCH(B7,Parameters!$A$20:$A$26,1)) -> 0.9 | C8: Dealer slab table
A9: Dealer Payout (₹) | B9: =Parameters!$E$5*Parameters!$E$6*B8 -> 27000 | C9: Base × 60% × slab
A10: Kerala Volume Target (L) | B10: =SUM('TSO Incentive'!$K$5:$K$18) -> 10400 | C10: From TSO sheet
A11: Kerala Net Volume (L) | B11: =SUM('TSO Incentive'!$L$5:$L$18) -> 10600 | C11: From TSO sheet
A12: Volume Achievement % | B12: =IFERROR(B11/B10,0) -> 1.0192308
A13: Volume Slab % | B13: =INDEX(Parameters!$C$30:$C$35,MATCH(B12,Parameters!$A$30:$A$35,1)) -> 1 | C13: Volume slab table
A14: Volume Payout (₹) | B14: =Parameters!$E$5*Parameters!$E$7*B13 -> 20000 | C14: Base × 40% × slab
A15: Dealers beyond 280 | B15: =MAX(0,B6-B5) -> 0
A16: Extra Dealer Bonus (₹) | B16: =B15*Parameters!$E$8 -> 0
A17: Kerala Collection % | B17: 0.92 | C17: input – % of campaign epoxy billing collected by 31-Jan-27
A18: Region Bonus Condition | B18: =IF(AND(B7>=1,B17>=Parameters!$B$50),"Met","Not met") -> Not met | C18: 280 dealers AND collection ≥ threshold
A19: Region Bonus (₹) | B19: =IF(B18="Met",Parameters!$E$12,0) -> 0
A20: Gross before Cap (₹) | B20: =B9+B14+B16+B19 -> 47000
A21: Cap (₹) | B21: =Parameters!$E$13*Parameters!$E$5 -> 100000
A22: Collection Factor | B22: =INDEX(Parameters!$C$39:$C$41,MATCH(B17,Parameters!$A$39:$A$41,1)) -> 1
A23: FINAL PAYOUT (₹) | B23: =IF(B7<Parameters!$B$51,0,MIN(B20,B21)*B22) -> 47000 | C23: 0 if below gate
